<mujoco model="panda">
  <compiler angle="radian" meshdir="assets" autolimits="true"/>

  <option integrator="implicitfast"/>

  <default>
    <default class="panda">
      <material specular="0.5" shininess="0.25"/>
      <joint armature="0.1" damping="1" axis="0 0 1" range="-2.8973 2.8973"/>
      <general dyntype="none" biastype="affine" ctrlrange="-2.8973 2.8973" forcerange="-87 87"/>
      <default class="finger">
        <joint axis="0 1 0" type="slide" range="0 0.04"/>
      </default>

      <default class="visual">
        <geom type="mesh" contype="0" conaffinity="0" group="2"/>
      </default>
      <default class="collision">
        <geom type="mesh" group="3"/>
        <default class="fingertip_pad_collision_1">
          <geom type="box" size="0.0085 0.004 0.0085" pos="0 0.0055 0.0445"/>
        </default>
        <default class="fingertip_pad_collision_2">
          <geom type="box" size="0.003 0.002 0.003" pos="0.0055 0.002 0.05"/>
        </default>
        <default class="fingertip_pad_collision_3">
          <geom type="box" size="0.003 0.002 0.003" pos="-0.0055 0.002 0.05"/>
        </default>
        <default class="fingertip_pad_collision_4">
          <geom type="box" size="0.003 0.002 0.0035" pos="0.0055 0.002 0.0395"/>
        </default>
        <default class="fingertip_pad_collision_5">
          <geom type="box" size="0.003 0.002 0.0035" pos="-0.0055 0.002 0.0395"/>
        </default>
      </default>
    </default>
  </default>

  <asset>
    <material class="panda" name="white" rgba="1 1 1 1"/>
    <material class="panda" name="off_white" rgba="0.901961 0.921569 0.929412 1"/>
    <material class="panda" name="black" rgba="0.25 0.25 0.25 1"/>
    <material class="panda" name="green" rgba="0 1 0 1"/>
    <material class="panda" name="light_blue" rgba="0.039216 0.541176 0.780392 1"/>

    <!-- Collision meshes -->
    <mesh name="link0_c" file="link0.stl"/>
    <mesh name="link1_c" file="link1.stl"/>
    <mesh name="link2_c" file="link2.stl"/>
    <mesh name="link3_c" file="link3.stl"/>
    <mesh name="link4_c" file="link4.stl"/>
    <mesh name="link5_c0" file="link5_collision_0.obj"/>
    <mesh name="link5_c1" file="link5_collision_1.obj"/>
    <mesh name="link5_c2" file="link5_collision_2.obj"/>
    <mesh name="link6_c" file="link6.stl"/>
    <mesh name="link7_c" file="link7.stl"/>
    <mesh name="hand_c" file="hand.stl"/>

    <!-- Visual meshes -->
    <mesh file="link0_0.obj"/>
    <mesh file="link0_1.obj"/>
    <mesh file="link0_2.obj"/>
    <mesh file="link0_3.obj"/>
    <mesh file="link0_4.obj"/>
    <mesh file="link0_5.obj"/>
    <mesh file="link0_7.obj"/>
    <mesh file="link0_8.obj"/>
    <mesh file="link0_9.obj"/>
    <mesh file="link0_10.obj"/>
    <mesh file="link0_11.obj"/>
    <mesh file="link1.obj"/>
    <mesh file="link2.obj"/>
    <mesh file="link3_0.obj"/>
    <mesh file="link3_1.obj"/>
    <mesh file="link3_2.obj"/>
    <mesh file="link3_3.obj"/>
    <mesh file="link4_0.obj"/>
    <mesh file="link4_1.obj"/>
    <mesh file="link4_2.obj"/>
    <mesh file="link4_3.obj"/>
    <mesh file="link5_0.obj"/>
    <mesh file="link5_1.obj"/>
    <mesh file="link5_2.obj"/>
    <mesh file="link6_0.obj"/>
    <mesh file="link6_1.obj"/>
    <mesh file="link6_2.obj"/>
    <mesh file="link6_3.obj"/>
    <mesh file="link6_4.obj"/>
    <mesh file="link6_5.obj"/>
    <mesh file="link6_6.obj"/>
    <mesh file="link6_7.obj"/>
    <mesh file="link6_8.obj"/>
    <mesh file="link6_9.obj"/>
    <mesh file="link6_10.obj"/>
    <mesh file="link6_11.obj"/>
    <mesh file="link6_12.obj"/>
    <mesh file="link6_13.obj"/>
    <mesh file="link6_14.obj"/>
    <mesh file="link6_15.obj"/>
    <mesh file="link6_16.obj"/>
    <mesh file="link7_0.obj"/>
    <mesh file="link7_1.obj"/>
    <mesh file="link7_2.obj"/>
    <mesh file="link7_3.obj"/>
    <mesh file="link7_4.obj"/>
    <mesh file="link7_5.obj"/>
    <mesh file="link7_6.obj"/>
    <mesh file="link7_7.obj"/>
    <mesh file="hand_0.obj"/>
    <mesh file="hand_1.obj"/>
    <mesh file="hand_2.obj"/>
    <mesh file="hand_3.obj"/>
    <mesh file="hand_4.obj"/>
    <mesh file="finger_0.obj"/>
    <mesh file="finger_1.obj"/>

    <!-- Meshes for the hole -->
    <mesh file="geometry_0.stl"/>
    <mesh file="geometry_1.stl"/>
    <mesh file="geometry_2.stl"/>
    <mesh file="geometry_3.stl"/>
    <mesh file="geometry_4.stl"/>
    <mesh file="geometry_5.stl"/>
    <mesh file="geometry_6.stl"/>
    <mesh file="geometry_7.stl"/>
    <mesh file="geometry_8.stl"/>
    <mesh file="geometry_9.stl"/>
    <mesh file="geometry_10.stl"/>
    <mesh file="geometry_11.stl"/>
    <mesh file="geometry_12.stl"/>
    <mesh file="geometry_13.stl"/>
    <mesh file="geometry_14.stl"/>
    <mesh file="geometry_15.stl"/>
    <mesh file="geometry_16.stl"/>
    <mesh file="geometry_17.stl"/>
    <mesh file="geometry_18.stl"/>
    <mesh file="geometry_19.stl"/>
    <mesh file="geometry_20.stl"/>
    <mesh file="geometry_21.stl"/>
    <mesh file="geometry_22.stl"/>
    <mesh file="geometry_23.stl"/>
    <mesh file="geometry_24.stl"/>
    <mesh file="geometry_25.stl"/>
    <mesh file="geometry_26.stl"/>
    <mesh file="geometry_27.stl"/>
    <mesh file="geometry_28.stl"/>
    <mesh file="geometry_29.stl"/>
    <mesh file="geometry_30.stl"/>
    <mesh file="geometry_31.stl"/>
    <mesh file="geometry_32.stl"/>
    <mesh file="geometry_33.stl"/>
    <mesh file="geometry_34.stl"/>
    <mesh file="geometry_35.stl"/>
    <mesh file="geometry_36.stl"/>
    <mesh file="geometry_37.stl"/>
    <mesh file="geometry_38.stl"/>
    <mesh file="geometry_39.stl"/>
    <mesh file="geometry_40.stl"/>
    <mesh file="geometry_41.stl"/>
    <mesh file="geometry_42.stl"/>
    <mesh file="geometry_43.stl"/>
    <mesh file="geometry_44.stl"/>
    <mesh file="geometry_45.stl"/>
    <mesh file="geometry_46.stl"/>
    <mesh file="geometry_47.stl"/>
    <mesh file="geometry_48.stl"/>
    <mesh file="geometry_49.stl"/>
    <mesh file="geometry_50.stl"/>
    <mesh file="geometry_51.stl"/>
    <mesh file="geometry_52.stl"/>
    <mesh file="geometry_53.stl"/>
    <mesh file="geometry_54.stl"/>
    <mesh file="geometry_55.stl"/>
    <mesh file="geometry_56.stl"/>
    <mesh file="geometry_57.stl"/>
    <mesh file="geometry_58.stl"/>
    <mesh file="geometry_59.stl"/>
    <mesh file="geometry_60.stl"/>
    <mesh file="geometry_61.stl"/>
    <mesh file="geometry_62.stl"/>
    <mesh file="geometry_63.stl"/>
    <mesh file="geometry_64.stl"/>
    <mesh file="geometry_65.stl"/>
    <mesh file="geometry_66.stl"/>
    <mesh file="geometry_67.stl"/>
    <mesh file="geometry_68.stl"/>
    <mesh file="geometry_69.stl"/>
    <mesh file="geometry_70.stl"/>
    <mesh file="geometry_71.stl"/>
    <mesh file="geometry_72.stl"/>
    <mesh file="geometry_73.stl"/>
    <mesh file="geometry_74.stl"/>
    <mesh file="geometry_75.stl"/>
    <mesh file="geometry_76.stl"/>
    <mesh file="geometry_77.stl"/>
    <mesh file="geometry_78.stl"/>
    <mesh file="geometry_79.stl"/>

    <mesh file="bevel_peg.stl"/>
  </asset>

  <worldbody>
    <light name="top" pos="0 0 2" mode="trackcom"/>
    <body name="link0" childclass="panda">
      <inertial mass="0.629769" pos="-0.041018 -0.00014 0.049974"
        fullinertia="0.00315 0.00388 0.004285 8.2904e-7 0.00015 8.2299e-6"/>
      <geom mesh="link0_0" material="off_white" class="visual"/>
      <geom mesh="link0_1" material="black" class="visual"/>
      <geom mesh="link0_2" material="off_white" class="visual"/>
      <geom mesh="link0_3" material="black" class="visual"/>
      <geom mesh="link0_4" material="off_white" class="visual"/>
      <geom mesh="link0_5" material="black" class="visual"/>
      <geom mesh="link0_7" material="white" class="visual"/>
      <geom mesh="link0_8" material="white" class="visual"/>
      <geom mesh="link0_9" material="black" class="visual"/>
      <geom mesh="link0_10" material="off_white" class="visual"/>
      <geom mesh="link0_11" material="white" class="visual"/>
      <geom mesh="link0_c" class="collision"/>
      <body name="link1" pos="0 0 0.333">
        <inertial mass="4.970684" pos="0.003875 0.002081 -0.04762"
          fullinertia="0.70337 0.70661 0.0091170 -0.00013900 0.0067720 0.019169"/>
        <joint name="panda_joint1"/>
        <geom material="white" mesh="link1" class="visual"/>
        <geom mesh="link1_c" class="collision"/>
        <body name="link2" quat="1 -1 0 0">
          <inertial mass="0.646926" pos="-0.003141 -0.02872 0.003495"
            fullinertia="0.0079620 2.8110e-2 2.5995e-2 -3.925e-3 1.0254e-2 7.04e-4"/>
          <joint name="panda_joint2" range="-1.7628 1.7628"/>
          <geom material="white" mesh="link2" class="visual"/>
          <geom mesh="link2_c" class="collision"/>
          <body name="link3" pos="0 -0.316 0" quat="1 1 0 0">
            <joint name="panda_joint3"/>
            <inertial mass="3.228604" pos="2.7518e-2 3.9252e-2 -6.6502e-2"
              fullinertia="3.7242e-2 3.6155e-2 1.083e-2 -4.761e-3 -1.1396e-2 -1.2805e-2"/>
            <geom mesh="link3_0" material="white" class="visual"/>
            <geom mesh="link3_1" material="white" class="visual"/>
            <geom mesh="link3_2" material="white" class="visual"/>
            <geom mesh="link3_3" material="black" class="visual"/>
            <geom mesh="link3_c" class="collision"/>
            <body name="link4" pos="0.0825 0 0" quat="1 1 0 0">
              <inertial mass="3.587895" pos="-5.317e-2 1.04419e-1 2.7454e-2"
                fullinertia="2.5853e-2 1.9552e-2 2.8323e-2 7.796e-3 -1.332e-3 8.641e-3"/>
              <joint name="panda_joint4" range="-3.0718 -0.0698"/>
              <geom mesh="link4_0" material="white" class="visual"/>
              <geom mesh="link4_1" material="white" class="visual"/>
              <geom mesh="link4_2" material="black" class="visual"/>
              <geom mesh="link4_3" material="white" class="visual"/>
              <geom mesh="link4_c" class="collision"/>
              <body name="link5" pos="-0.0825 0.384 0" quat="1 -1 0 0">
                <inertial mass="1.225946" pos="-1.1953e-2 4.1065e-2 -3.8437e-2"
                  fullinertia="3.5549e-2 2.9474e-2 8.627e-3 -2.117e-3 -4.037e-3 2.29e-4"/>
                <joint name="panda_joint5"/>
                <geom mesh="link5_0" material="black" class="visual"/>
                <geom mesh="link5_1" material="white" class="visual"/>
                <geom mesh="link5_2" material="white" class="visual"/>
                <geom mesh="link5_c0" class="collision"/>
                <geom mesh="link5_c1" class="collision"/>
                <geom mesh="link5_c2" class="collision"/>
                <body name="link6" quat="1 1 0 0">
                  <inertial mass="1.666555" pos="6.0149e-2 -1.4117e-2 -1.0517e-2"
                    fullinertia="1.964e-3 4.354e-3 5.433e-3 1.09e-4 -1.158e-3 3.41e-4"/>
                  <joint name="panda_joint6" range="-0.0175 3.7525"/>
                  <geom mesh="link6_0" material="off_white" class="visual"/>
                  <geom mesh="link6_1" material="white" class="visual"/>
                  <geom mesh="link6_2" material="black" class="visual"/>
                  <geom mesh="link6_3" material="white" class="visual"/>
                  <geom mesh="link6_4" material="white" class="visual"/>
                  <geom mesh="link6_5" material="white" class="visual"/>
                  <geom mesh="link6_6" material="white" class="visual"/>
                  <geom mesh="link6_7" material="light_blue" class="visual"/>
                  <geom mesh="link6_8" material="light_blue" class="visual"/>
                  <geom mesh="link6_9" material="black" class="visual"/>
                  <geom mesh="link6_10" material="black" class="visual"/>
                  <geom mesh="link6_11" material="white" class="visual"/>
                  <geom mesh="link6_12" material="green" class="visual"/>
                  <geom mesh="link6_13" material="white" class="visual"/>
                  <geom mesh="link6_14" material="black" class="visual"/>
                  <geom mesh="link6_15" material="black" class="visual"/>
                  <geom mesh="link6_16" material="white" class="visual"/>
                  <geom mesh="link6_c" class="collision"/>
                  <body name="link7" pos="0.088 0 0" quat="1 1 0 0">
                    <inertial mass="7.35522e-01" pos="1.0517e-2 -4.252e-3 6.1597e-2"
                      fullinertia="1.2516e-2 1.0027e-2 4.815e-3 -4.28e-4 -1.196e-3 -7.41e-4"/>
                    <joint name="panda_joint7"/>
                    <geom mesh="link7_0" material="white" class="visual"/>
                    <geom mesh="link7_1" material="black" class="visual"/>
                    <geom mesh="link7_2" material="black" class="visual"/>
                    <geom mesh="link7_3" material="black" class="visual"/>
                    <geom mesh="link7_4" material="black" class="visual"/>
                    <geom mesh="link7_5" material="black" class="visual"/>
                    <geom mesh="link7_6" material="black" class="visual"/>
                    <geom mesh="link7_7" material="white" class="visual"/>
                    <geom mesh="link7_c" class="collision"/>
                    <site name="ft_sensor_site" pos="0 0 0"/>
                    <body name="hand" pos="0 0 0.107" quat="0.9238795 0 0 -0.3826834">
                      <inertial mass="0.73" pos="-0.01 0 0.03" diaginertia="0.001 0.0025 0.0017"/>
                      <geom mesh="hand_0" material="off_white" class="visual"/>
                      <geom mesh="hand_1" material="black" class="visual"/>
                      <geom mesh="hand_2" material="black" class="visual"/>
                      <geom mesh="hand_3" material="white" class="visual"/>
                      <geom mesh="hand_4" material="off_white" class="visual"/>
                      <geom mesh="hand_c" class="collision"/>
                      <body name="peg" pos="0.0 0 0.115">
                        <geom type="mesh" mesh="bevel_peg" quat="0 1 0 0" rgba="0 1 0 1"/>
                        <inertial pos="0 0 0" mass="0.1" diaginertia="0.1 0.1 0.1" />
                      </body>
                      <body name="left_finger" pos="0 0 0.0584">
                        <inertial mass="0.015" pos="0 0 0" diaginertia="2.375e-6 2.375e-6 7.5e-7"/>
                        <joint name="panda_finger_joint1" class="finger"/>
                        <geom mesh="finger_0" material="off_white" class="visual"/>
                        <geom mesh="finger_1" material="black" class="visual"/>
                        <geom mesh="finger_0" class="collision"/>
                        <geom class="fingertip_pad_collision_1"/>
                        <geom class="fingertip_pad_collision_2"/>
                        <geom class="fingertip_pad_collision_3"/>
                        <geom class="fingertip_pad_collision_4"/>
                        <geom class="fingertip_pad_collision_5"/>
                      </body>
                      <body name="right_finger" pos="0 0 0.0584" quat="0 0 0 1">
                        <inertial mass="0.015" pos="0 0 0" diaginertia="2.375e-6 2.375e-6 7.5e-7"/>
                        <joint name="panda_finger_joint2" class="finger"/>
                        <geom mesh="finger_0" material="off_white" class="visual"/>
                        <geom mesh="finger_1" material="black" class="visual"/>
                        <geom mesh="finger_0" class="collision"/>
                        <geom class="fingertip_pad_collision_1"/>
                        <geom class="fingertip_pad_collision_2"/>
                        <geom class="fingertip_pad_collision_3"/>
                        <geom class="fingertip_pad_collision_4"/>
                        <geom class="fingertip_pad_collision_5"/>
                      </body>
                    </body>
                  </body>
                </body>
              </body>
            </body>
          </body>
        </body>
      </body>
    </body>
    <body name="hole" pos="0.5 0. 0.01">
      <geom type="mesh" mesh="geometry_0"  rgba="1 0 0 1"/>
      <geom type="mesh" mesh="geometry_1"  rgba="1 0 0 1"/>
      <geom type="mesh" mesh="geometry_2"  rgba="1 0 0 1"/>
      <geom type="mesh" mesh="geometry_3"  rgba="1 0 0 1"/>
      <geom type="mesh" mesh="geometry_4"  rgba="1 0 0 1"/>
      <geom type="mesh" mesh="geometry_5"  rgba="1 0 0 1"/>
      <geom type="mesh" mesh="geometry_6"  rgba="1 0 0 1"/>
      <geom type="mesh" mesh="geometry_7"  rgba="1 0 0 1"/>
      <geom type="mesh" mesh="geometry_8"  rgba="1 0 0 1"/>
      <geom type="mesh" mesh="geometry_9"  rgba="1 0 0 1"/>
      <geom type="mesh" mesh="geometry_10" rgba="1 0 0 1" />
      <geom type="mesh" mesh="geometry_11" rgba="1 0 0 1" />
      <geom type="mesh" mesh="geometry_12" rgba="1 0 0 1" />
      <geom type="mesh" mesh="geometry_13" rgba="1 0 0 1" />
      <geom type="mesh" mesh="geometry_14" rgba="1 0 0 1" />
      <geom type="mesh" mesh="geometry_15" rgba="1 0 0 1" />
      <geom type="mesh" mesh="geometry_16" rgba="1 0 0 1" />
      <geom type="mesh" mesh="geometry_17" rgba="1 0 0 1" />
      <geom type="mesh" mesh="geometry_18" rgba="1 0 0 1" />
      <geom type="mesh" mesh="geometry_19" rgba="1 0 0 1" />
      <geom type="mesh" mesh="geometry_20" rgba="1 0 0 1" />
      <geom type="mesh" mesh="geometry_21" rgba="1 0 0 1" />
      <geom type="mesh" mesh="geometry_22" rgba="1 0 0 1" />
      <geom type="mesh" mesh="geometry_23" rgba="1 0 0 1" />
      <geom type="mesh" mesh="geometry_24" rgba="1 0 0 1" />
      <geom type="mesh" mesh="geometry_25" rgba="1 0 0 1" />
      <geom type="mesh" mesh="geometry_26" rgba="1 0 0 1" />
      <geom type="mesh" mesh="geometry_27" rgba="1 0 0 1" />
      <geom type="mesh" mesh="geometry_28" rgba="1 0 0 1" />
      <geom type="mesh" mesh="geometry_29" rgba="1 0 0 1" />
      <geom type="mesh" mesh="geometry_30" rgba="1 0 0 1" />
      <geom type="mesh" mesh="geometry_31" rgba="1 0 0 1" />
      <geom type="mesh" mesh="geometry_32" rgba="1 0 0 1" />
      <geom type="mesh" mesh="geometry_33" rgba="1 0 0 1" />
      <geom type="mesh" mesh="geometry_34" rgba="1 0 0 1" />
      <geom type="mesh" mesh="geometry_35" rgba="1 0 0 1" />
      <geom type="mesh" mesh="geometry_36" rgba="1 0 0 1" />
      <geom type="mesh" mesh="geometry_37" rgba="1 0 0 1" />
      <geom type="mesh" mesh="geometry_38" rgba="1 0 0 1" />
      <geom type="mesh" mesh="geometry_39" rgba="1 0 0 1" />
      <geom type="mesh" mesh="geometry_40" rgba="1 0 0 1" />
      <geom type="mesh" mesh="geometry_41" rgba="1 0 0 1" />
      <geom type="mesh" mesh="geometry_42" rgba="1 0 0 1" />
      <geom type="mesh" mesh="geometry_43" rgba="1 0 0 1" />
      <geom type="mesh" mesh="geometry_44" rgba="1 0 0 1" />
      <geom type="mesh" mesh="geometry_45" rgba="1 0 0 1" />
      <geom type="mesh" mesh="geometry_46" rgba="1 0 0 1" />
      <geom type="mesh" mesh="geometry_47" rgba="1 0 0 1" />
      <geom type="mesh" mesh="geometry_48" rgba="1 0 0 1" />
      <geom type="mesh" mesh="geometry_49" rgba="1 0 0 1" />
      <geom type="mesh" mesh="geometry_50" rgba="1 0 0 1" />
      <geom type="mesh" mesh="geometry_51" rgba="1 0 0 1" />
      <geom type="mesh" mesh="geometry_52" rgba="1 0 0 1" />
      <geom type="mesh" mesh="geometry_53" rgba="1 0 0 1" />
      <geom type="mesh" mesh="geometry_54" rgba="1 0 0 1" />
      <geom type="mesh" mesh="geometry_55" rgba="1 0 0 1" />
      <geom type="mesh" mesh="geometry_56" rgba="1 0 0 1" />
      <geom type="mesh" mesh="geometry_57" rgba="1 0 0 1" />
      <geom type="mesh" mesh="geometry_58" rgba="1 0 0 1" />
      <geom type="mesh" mesh="geometry_59" rgba="1 0 0 1" />
      <geom type="mesh" mesh="geometry_60" rgba="1 0 0 1" />
      <geom type="mesh" mesh="geometry_61" rgba="1 0 0 1" />
      <geom type="mesh" mesh="geometry_62" rgba="1 0 0 1" />
      <geom type="mesh" mesh="geometry_63" rgba="1 0 0 1" />
      <geom type="mesh" mesh="geometry_64" rgba="1 0 0 1" />
      <geom type="mesh" mesh="geometry_65" rgba="1 0 0 1" />
      <geom type="mesh" mesh="geometry_66" rgba="1 0 0 1" />
      <geom type="mesh" mesh="geometry_67" rgba="1 0 0 1" />
      <geom type="mesh" mesh="geometry_68" rgba="1 0 0 1" />
      <geom type="mesh" mesh="geometry_69" rgba="1 0 0 1" />
      <geom type="mesh" mesh="geometry_70" rgba="1 0 0 1" />
      <geom type="mesh" mesh="geometry_71" rgba="1 0 0 1" />
      <geom type="mesh" mesh="geometry_72" rgba="1 0 0 1" />
      <geom type="mesh" mesh="geometry_73" rgba="1 0 0 1" />
      <geom type="mesh" mesh="geometry_74" rgba="1 0 0 1" />
      <geom type="mesh" mesh="geometry_75" rgba="1 0 0 1" />
      <geom type="mesh" mesh="geometry_76" rgba="1 0 0 1" />
      <geom type="mesh" mesh="geometry_77" rgba="1 0 0 1" />
      <geom type="mesh" mesh="geometry_78" rgba="1 0 0 1" />
      <geom type="mesh" mesh="geometry_79" rgba="1 0 0 1" />
    </body>
  </worldbody>

  <sensor>
    <force name="ft_sensor_force" site="ft_sensor_site"/>
    <torque name="ft_sensor_torque" site="ft_sensor_site"/>
  </sensor>

  <tendon>
    <fixed name="split">
      <joint joint="panda_finger_joint1" coef="0.5"/>
      <joint joint="panda_finger_joint2" coef="0.5"/>
    </fixed>
  </tendon>

  <equality>
    <joint joint1="panda_finger_joint1" joint2="panda_finger_joint2" solimp="0.95 0.99 0.001" solref="0.005 1"/>
  </equality>

  <actuator>
    <!-- Remap original ctrlrange (0, 0.04) to (0, 255): 0.04 * 100 / 255 = 0.01568627451 -->
    <general class="panda" name="actuator8" tendon="split" forcerange="-100 100" ctrlrange="0 255"
      gainprm="0.01568627451 0 0" biasprm="0 -100 -10"/>
  </actuator>
</mujoco>
